Workbook

Sheet Resumen
A1: E6 - Analisis de costos: Pipeline de Analisis Inteligente (Proyecto B)
A2: Estimacion mensual de tokens, compute, almacenamiento y red. Comparativa entre las tres modalidades (2.3 en dos variantes).
A4: Como usar este libro
A5: 1) Revisa y ajusta las celdas azules en la hoja Supuestos (las amarillas son las mas sensibles).
A6: 2) Reemplaza los supuestos del equipo por tus mediciones: latencia por articulo (backend/results/benchmark.md), volumen real y tarifa electrica local.
A7: 3) Costos = detalle del volumen base; Escenarios = como cambia el costo al crecer el volumen. Todo se recalcula solo.
A9: Resultado al volumen base | B9: =Supuestos!$B$6 -> 10000
A10: Modalidad | B10: Total USD/mes | C10: USD por articulo | D10: USD por 1.000 articulos | E10: Instancias / nodos
A11: 2.1 GCP Console | B11: =Costos!B36 -> 92.42995 | C11: =Costos!B37 -> 0.009242995 | D11: =Costos!B38 -> 9.242995 | E11: =Costos!B15 -> 0
A12: 2.2 ADK + GCP | B12: =Costos!C36 -> 142.0252 | C12: =Costos!C37 -> 0.01420252 | D12: =Costos!C38 -> 14.20252 | E12: =Costos!C15 -> 0
A13: 2.3-A Ollama equipo propio | B13: =Costos!D36 -> 35.913333 | C13: =Costos!D37 -> 0.0035913333 | D13: =Costos!D38 -> 3.5913333 | E13: =Costos!D15 -> 1
A14: 2.3-B Ollama VM en nube | B14: =Costos!E36 -> 102.964 | C14: =Costos!E37 -> 0.0102964 | D14: =Costos!E38 -> 10.2964 | E14: =Costos!E15 -> 1
A15: Modalidad mas barata (solo costo): | B15: =INDEX(A11:A14,MATCH(MIN(B11:B14),B11:B14,0)) -> 2.3-A Ollama equipo propio
A16: Modalidad mas cara: | B16: =INDEX(A11:A14,MATCH(MAX(B11:B14),B11:B14,0)) -> 2.2 ADK + GCP
A18: Sensibilidad: costo de tokens cloud segun la tarifa de Vertex AI
A19: Tarifa | B19: 2.1 USD/mes | C19: 2.2 USD/mes
A20: Introductoria (hasta 31-dic-2026) | B20: =Supuestos!$B$6*(Supuestos!$B$20*Supuestos!$B$23*1)/1000000*Supuestos!$B$28+Supuestos!$B$6*((Supuestos!$B$21+Supuestos!$B$22*Supuestos!$B$24)*Supuestos!$B$23*1)/1000000*Supuestos!$B$29 -> 40.989375 | C20: =Supuestos!$B$6*(Supuestos!$B$20*Supuestos!$B$23*Supuestos!$B$48)/1000000*Supuestos!$B$28+Supuestos!$B$6*((Supuestos!$B$21+Supuestos!$B$22*Supuestos!$B$24)*Supuestos!$B$23*Supuestos!$B$48)/1000000*Supuestos!$B$29 -> 65.583
A21: Estandar (desde 1-ene-2027) | B21: =Supuestos!$B$6*(Supuestos!$B$20*Supuestos!$B$23*1)/1000000*Supuestos!$B$30+Supuestos!$B$6*((Supuestos!$B$21+Supuestos!$B$22*Supuestos!$B$24)*Supuestos!$B$23*1)/1000000*Supuestos!$B$31 -> 81.97875 | C21: =Supuestos!$B$6*(Supuestos!$B$20*Supuestos!$B$23*Supuestos!$B$48)/1000000*Supuestos!$B$30+Supuestos!$B$6*((Supuestos!$B$21+Supuestos!$B$22*Supuestos!$B$24)*Supuestos!$B$23*Supuestos!$B$48)/1000000*Supuestos!$B$31 -> 131.166
A23: Hallazgos (validos con los supuestos base; relee los numeros si cambias las entradas)
A24: - 2.1 y 2.2: el costo crece casi en proporcion al volumen porque lo domina el costo de tokens.
A25: - 2.2 cuesta mas que 2.1 por el ciclo ReAct (mas tokens y mas tiempo de instancia); el multiplicador x1,6 es un supuesto a medir.
A26: - 2.3-A: el costo es casi fijo (equipo + energia) y da saltos al agregar nodos; depende de la latencia real por articulo.
A27: - 2.3-B: una VM 24/7 se paga aunque este ociosa; a volumen bajo suele costar mas que una API gestionada.
A28: - La tarifa introductoria de Vertex AI termina el 31-dic-2026: el costo cloud puede duplicarse en 2027 (ver sensibilidad).
A29: - El costo NO mide calidad: un modelo de 3B puede exigir mas revision manual; tampoco incluye mano de obra ni mantenimiento.
A30: - Todos los precios cloud deben reconfirmarse en la calculadora de Google Cloud antes de decidir (ver hoja Notas y fuentes).

Sheet Supuestos
A1: Supuestos y entradas del modelo de costos
A2: Azul = dato de entrada editable | Azul con fondo amarillo = supuesto clave | Negro = formula. Cambia solo las celdas azules.
A4: Concepto | B4: Valor | C4: Unidad | D4: Fuente / estado
A5: A. Volumen y datos
A6: Articulos procesados por mes (volumen base) | B6: 10000 | C6: articulos/mes | D6: Supuesto del equipo: reemplazar con el volumen real de MediaGroup
A7: Meses de retencion de datos en la base | B7: 12 | C7: meses | D7: Supuesto del equipo: reemplazar/medir
A8: Tamano almacenado por articulo (entrada + resultado + metricas) | B8: 8 | C8: KB | D8: Supuesto del equipo: reemplazar/medir (medir con SQLite)
A9: Solicitudes HTTP por articulo (ingesta + consultas + dashboard) | B9: 8 | C9: solicitudes | D9: Supuesto del equipo: reemplazar/medir
A10: Datos de salida por articulo (callback + respuestas al frontend) | B10: 40 | C10: KB | D10: Supuesto del equipo: reemplazar/medir
A11: Logs generados por articulo | B11: 4 | C11: KB | D11: Supuesto del equipo: reemplazar/medir (~12 eventos JSON)
A13: B. Tokens por articulo (de RFC-001, seccion 7)
A14: 04 Analizar - tokens de entrada | B14: 1360 | C14: tokens | D14: Hipotesis RFC; medir con benchmark_ollama.py
A15: 04 Analizar - tokens de salida | B15: 15 | C15: tokens | D15: Hipotesis RFC
A16: 05 Enriquecer - tokens de entrada | B16: 1420 | C16: tokens | D16: Hipotesis RFC
A17: 05 Enriquecer - tokens de salida | B17: 150 | C17: tokens | D17: Hipotesis RFC
A18: 06 Resumen SEO - tokens de entrada | B18: 1350 | C18: tokens | D18: Hipotesis RFC
A19: 06 Resumen SEO - tokens de salida | B19: 50 | C19: tokens | D19: Hipotesis RFC
A20: Tokens de entrada por articulo | B20: =$B$14+$B$16+$B$18 -> 4130 | C20: tokens | D20: Formula
A21: Tokens de salida por articulo | B21: =$B$15+$B$17+$B$19 -> 215 | C21: tokens | D21: Formula
A22: Llamadas LLM por articulo | B22: 3 | C22: llamadas | D22: Diseno del pipeline (etapas 04, 05, 06)
A23: Factor de reintentos | B23: 1.05 | C23: x | D23: Supuesto del equipo: reemplazar/medir (reintento del resumen SEO)
A24: Tokens de razonamiento extra por llamada (solo modelos cloud) | B24: 0 | C24: tokens | D24: Supuesto: 0. Si el modelo usa 'thinking' se factura como salida; medir con compare_providers.py
A26: C. Precios Vertex AI (modelos Gemini Flash recientes)
A27: Tarifa a usar | B27: Estandar (2027) | C27: selector | D27: Elige: Introductoria (2026) o Estandar (2027). Se usa la estandar por prudencia.
A28: Introductoria: entrada | B28: 0.75 | C28: USD / 1M tokens | D28: Verificado 21-oct-2026 (Google Cloud): vigente hasta 31-dic-2026
A29: Introductoria: salida | B29: 3.75 | C29: USD / 1M tokens | D29: Verificado 21-oct-2026 (Google Cloud): vigente hasta 31-dic-2026
A30: Estandar: entrada | B30: 1.5 | C30: USD / 1M tokens | D30: Verificado 21-oct-2026 (Google Cloud): desde 1-ene-2027
A31: Estandar: salida | B31: 7.5 | C31: USD / 1M tokens | D31: Verificado 21-oct-2026 (Google Cloud): desde 1-ene-2027
A32: Precio de entrada en uso | B32: =IF($B$27="Introductoria (2026)",$B$28,$B$30) -> 1.5 | C32: USD / 1M tokens | D32: Formula
A33: Precio de salida en uso | B33: =IF($B$27="Introductoria (2026)",$B$29,$B$31) -> 7.5 | C33: USD / 1M tokens | D33: Formula
A35: D. Cloud Run (modalidades 2.1 y 2.2)
A36: Segundos de instancia por articulo (2.1) | B36: 10 | C36: s | D36: Supuesto del equipo: reemplazar/medir (3 llamadas cloud + overhead); medir en despliegue
A37: vCPU por instancia | B37: 1 | C37: vCPU | D37: Supuesto del equipo: reemplazar/medir
A38: Memoria por instancia | B38: 1 | C38: GiB | D38: Supuesto del equipo: reemplazar/medir
A39: Instancias minimas siempre activas | B39: 0 | C39: instancias | D39: Supuesto del equipo: reemplazar/medir (0 = escala a cero, con arranque en frio)
A40: Precio CPU | B40: 2.4e-05 | C40: USD / vCPU-s | D40: Fuente secundaria (ver Notas); hay fuentes con tarifa menor (0.000018)
A41: Precio memoria | B41: 2.5e-06 | C41: USD / GiB-s | D41: Fuente secundaria (ver Notas)
A42: Precio solicitudes | B42: 0.4 | C42: USD / 1M | D42: Fuente secundaria (ver Notas)
A43: Capa gratuita CPU | B43: 180000 | C43: vCPU-s/mes | D43: Fuente secundaria (ver Notas)
A44: Capa gratuita memoria | B44: 360000 | C44: GiB-s/mes | D44: Fuente secundaria (ver Notas)
...

Sheet Costos
A1: Costo mensual detallado por modalidad (volumen base)
A2: Todas las celdas son formulas que leen la hoja Supuestos. Categorias pedidas: tokens, compute, almacenamiento y red.
A4: Concepto | B4: 2.1 GCP Console | C4: 2.2 ADK + GCP | D4: 2.3-A Ollama equipo propio | E4: 2.3-B Ollama VM en nube | F4: Notas
A5: TOKENS
A6: Articulos por mes | B6: =Supuestos!$B$6 -> 10000 | C6: =Supuestos!$B$6 -> 10000 | D6: =Supuestos!$B$6 -> 10000 | E6: =Supuestos!$B$6 -> 10000
A7: Tokens de entrada por articulo | B7: =Supuestos!$B$20*Supuestos!$B$23*1 -> 4336.5 | C7: =Supuestos!$B$20*Supuestos!$B$23*Supuestos!$B$48 -> 6938.4 | D7: =Supuestos!$B$20*Supuestos!$B$23*1 -> 4336.5 | E7: =Supuestos!$B$20*Supuestos!$B$23*1 -> 4336.5 | F7: Incluye reintentos; 2.2 multiplica por el ciclo ReAct
A8: Tokens de salida por articulo | B8: =(Supuestos!$B$21+Supuestos!$B$22*Supuestos!$B$24)*Supuestos!$B$23*1 -> 225.75 | C8: =(Supuestos!$B$21+Supuestos!$B$22*Supuestos!$B$24)*Supuestos!$B$23*Supuestos!$B$48 -> 361.2 | D8: =Supuestos!$B$21*Supuestos!$B$23 -> 225.75 | E8: =Supuestos!$B$21*Supuestos!$B$23 -> 225.75 | F8: Cloud suma tokens de razonamiento si se configuran
A9: Millones de tokens por mes | B9: =B6*(B7+B8)/1000000 -> 45.6225 | C9: =C6*(C7+C8)/1000000 -> 72.996 | D9: =D6*(D7+D8)/1000000 -> 45.6225 | E9: =E6*(E7+E8)/1000000 -> 45.6225
A10: Precio de entrada (USD / 1M) | B10: =Supuestos!$B$32 -> 1.5 | C10: =Supuestos!$B$32 -> 1.5 | D10: =0 -> 0 | E10: =0 -> 0 | F10: Local: sin costo por token
A11: Precio de salida (USD / 1M) | B11: =Supuestos!$B$33 -> 7.5 | C11: =Supuestos!$B$33 -> 7.5 | D11: =0 -> 0 | E11: =0 -> 0
A12: Costo de tokens (USD/mes) | B12: =B6*B7/1000000*B10+B6*B8/1000000*B11 -> 81.97875 | C12: =C6*C7/1000000*C10+C6*C8/1000000*C11 -> 131.166 | D12: =D6*D7/1000000*D10+D6*D8/1000000*D11 -> 0 | E12: =E6*E7/1000000*E10+E6*E8/1000000*E11 -> 0
A13: COMPUTE
A14: Segundos de proceso por articulo | B14: =Supuestos!$B$36 -> 10 | C14: =Supuestos!$B$36*Supuestos!$B$49 -> 16 | D14: =Supuestos!$B$64 -> 45 | E14: =Supuestos!$B$64 -> 45 | F14: Local: hipotesis a medir con el benchmark
A15: Instancias minimas (cloud) / nodos necesarios (local) | B15: =Supuestos!$B$39 -> 0 | C15: =Supuestos!$B$39 -> 0 | D15: =MAX(1,ROUNDUP(Supuestos!$B$6*Supuestos!$B$64/3600/(Supuestos!$B$66*Supuestos!$B$65),0)) -> 1 | E15: =MAX(1,ROUNDUP(Supuestos!$B$6*Supuestos!$B$64/3600/(Supuestos!$B$66*Supuestos!$B$65),0)) -> 1 | F15: Local: nodos para no pasar la utilizacion objetivo
A16: Utilizacion de capacidad (local) | B16: =0 -> 0 | C16: =0 -> 0 | D16: =Supuestos!$B$6*D14/3600/(D15*Supuestos!$B$66) -> 0.17123288 | E16: =Supuestos!$B$6*E14/3600/(E15*Supuestos!$B$66) -> 0.17123288 | F16: Cloud: escala automaticamente
A17: vCPU-segundos facturables (Cloud Run) | B17: =MAX(0,Supuestos!$B$6*B14*Supuestos!$B$37+Supuestos!$B$39*Supuestos!$B$37*2592000-Supuestos!$B$43) -> 0 | C17: =MAX(0,Supuestos!$B$6*C14*Supuestos!$B$37+Supuestos!$B$39*Supuestos!$B$37*2592000-Supuestos!$B$43) -> 0 | D17: =0 -> 0 | E17: =0 -> 0 | F17: Descuenta la capa gratuita
A18: GiB-segundos facturables (Cloud Run) | B18: =MAX(0,Supuestos!$B$6*B14*Supuestos!$B$38+Supuestos!$B$39*Supuestos!$B$38*2592000-Supuestos!$B$44) -> 0 | C18: =MAX(0,Supuestos!$B$6*C14*Supuestos!$B$38+Supuestos!$B$39*Supuestos!$B$38*2592000-Supuestos!$B$44) -> 0 | D18: =0 -> 0 | E18: =0 -> 0
A19: Solicitudes facturables (Cloud Run) | B19: =MAX(0,Supuestos!$B$6*Supuestos!$B$9-Supuestos!$B$45) -> 0 | C19: =MAX(0,Supuestos!$B$6*Supuestos!$B$9-Supuestos!$B$45) -> 0 | D19: =0 -> 0 | E19: =0 -> 0
A20: Costo Cloud Run (CPU + memoria + solicitudes) | B20: =B17*Supuestos!$B$40+B18*Supuestos!$B$41+B19/1000000*Supuestos!$B$42 -> 0 | C20: =C17*Supuestos!$B$40+C18*Supuestos!$B$41+C19/1000000*Supuestos!$B$42 -> 0 | D20: =0 -> 0 | E20: =0 -> 0
A21: Costo de equipo amortizado / VM 24/7 | B21: =0 -> 0 | C21: =0 -> 0 | D21: =D15*Supuestos!$B$67/Supuestos!$B$68 -> 33.333333 | E21: =E15*Supuestos!$B$72*Supuestos!$B$66 -> 97.82 | F21: 2.3-B paga la VM aunque este ociosa
A22: Costo de energia (equipo propio) | B22: =0 -> 0 | C22: =0 -> 0 | D22: =((Supuestos!$B$6*Supuestos!$B$64/3600)*Supuestos!$B$69+(D15*Supuestos!$B$66-(Supuestos!$B$6*Supuestos!$B$64/3600))*Supuestos!$B$70)/1000*Supuestos!$B$71 -> 2.58 | E22: =0 -> 0
A23: Costo de compute (USD/mes) | B23: =B20+B21+B22 -> 0 | C23: =C20+C21+C22 -> 0 | D23: =D20+D21+D22 -> 35.913333 | E23: =E20+E21+E22 -> 97.82
A24: ALMACENAMIENTO
A25: GB de datos retenidos | B25: =Supuestos!$B$6*(Supuestos!$B$8+0)*Supuestos!$B$7/1000000 -> 0.96 | C25: =Supuestos!$B$6*(Supuestos!$B$8+Supuestos!$B$50)*Supuestos!$B$7/1000000 -> 3.36 | D25: =Supuestos!$B$6*(Supuestos!$B$8+0)*Supuestos!$B$7/1000000 -> 0.96 | E25: =Supuestos!$B$6*(Supuestos!$B$8+0)*Supuestos!$B$7/1000000 -> 0.96 | F25: 2.2 incluye session memory
A26: GiB de logs por mes | B26: =Supuestos!$B$6*Supuestos!$B$11*1/1000000 -> 0.04 | C26: =Supuestos!$B$6*Supuestos!$B$11*Supuestos!$B$51/1000000 -> 0.08 | D26: =Supuestos!$B$6*Supuestos!$B$11*1/1000000 -> 0.04 | E26: =Supuestos!$B$6*Supuestos!$B$11*1/1000000 -> 0.04
A27: Costo de base de datos / disco | B27: =Supuestos!$B$54+B25*Supuestos!$B$55 -> 10.1632 | C27: =Supuestos!$B$54+C25*Supuestos!$B$55 -> 10.5712 | D27: =0 -> 0 | E27: =(Supuestos!$B$73+E25)*Supuestos!$B$74 -> 5.096 | F27: Equipo propio: disco incluido
A28: Costo de logging | B28: =MAX(0,B26-Supuestos!$B$57)*Supuestos!$B$56 -> 0 | C28: =MAX(0,C26-Supuestos!$B$57)*Supuestos!$B$56 -> 0 | D28: =0 -> 0 | E28: =0 -> 0 | F28: Local: journald en disco
A29: Costo de almacenamiento (USD/mes) | B29: =B27+B28 -> 10.1632 | C29: =C27+C28 -> 10.5712 | D29: =D27+D28 -> 0 | E29: =E27+E28 -> 5.096
A30: RED
A31: GiB de salida por mes | B31: =Supuestos!$B$6*Supuestos!$B$10/1000000 -> 0.4 | C31: =Supuestos!$B$6*Supuestos!$B$10/1000000 -> 0.4 | D31: =Supuestos!$B$6*Supuestos!$B$10/1000000 -> 0.4 | E31: =Supuestos!$B$6*Supuestos!$B$10/1000000 -> 0.4
A32: Costo de red (USD/mes) | B32: =MAX(0,B31-Supuestos!$B$61)*Supuestos!$B$60 -> 0.048 | C32: =MAX(0,C31-Supuestos!$B$61)*Supuestos!$B$60 -> 0.048 | D32: =0 -> 0 | E32: =MAX(0,E31-Supuestos!$B$61)*Supuestos!$B$60 -> 0.048 | F32: Equipo propio: sin cargo adicional (red existente)
A33: OTROS SERVICIOS
A34: Secret Manager (USD/mes) | B34: =Supuestos!$B$58*Supuestos!$B$59 -> 0.24 | C34: =Supuestos!$B$58*Supuestos!$B$59 -> 0.24 | D34: =0 -> 0 | E34: =0 -> 0 | F34: Local: secretos en .env (menor seguridad)
A35: TOTALES
A36: TOTAL MENSUAL (USD) | B36: =B12+B23+B29+B32+B34 -> 92.42995 | C36: =C12+C23+C29+C32+C34 -> 142.0252 | D36: =D12+D23+D29+D32+D34 -> 35.913333 | E36: =E12+E23+E29+E32+E34 -> 102.964
A37: Costo por articulo (USD) | B37: =IF(B6=0,0,B36/B6) -> 0.009242995 | C37: =IF(C6=0,0,C36/C6) -> 0.01420252 | D37: =IF(D6=0,0,D36/D6) -> 0.0035913333 | E37: =IF(E6=0,0,E36/E6) -> 0.0102964
A38: Costo por 1.000 articulos (USD) | B38: =B37*1000 -> 9.242995 | C38: =C37*1000 -> 14.20252 | D38: =D37*1000 -> 3.5913333 | E38: =E37*1000 -> 10.2964

Sheet Escenarios
A1: Escenarios de volumen: costo mensual total por modalidad
A2: Los volumenes (azul) se pueden editar. La ultima fila usa el volumen base de Supuestos y sirve de verificacion contra la hoja Costos.
A4: Articulos / mes | B4: 2.1 GCP Console (USD/mes) | C4: 2.2 ADK + GCP (USD/mes) | D4: 2.3-A Ollama equipo propio (USD/mes) | E4: 2.3-B Ollama VM en nube (USD/mes)
A5: 1000 | B5: =H16 -> 18.458995 | C5: =H17 -> 23.41852 | D5: =H18 -> 35.069583 | E5: =H19 -> 102.8344
A6: 5000 | B6: =H20 -> 51.334975 | C6: =H21 -> 76.1326 | D6: =H22 -> 35.444583 | E6: =H23 -> 102.892
A7: 10000 | B7: =H24 -> 92.42995 | C7: =H25 -> 142.0252 | D7: =H26 -> 35.913333 | E7: =H27 -> 102.964
A8: 50000 | B8: =H28 -> 429.21975 | C8: =H29 -> 685.146 | D8: =H30 -> 74.639167 | E8: =H31 -> 201.36
A9: 100000 | B9: =H32 -> 853.4195 | C9: =H33 -> 1365.272 | D9: =H34 -> 114.3025 | E9: =H35 -> 299.9
A10: 500000 | B10: =H36 -> 4247.8175 | C10: =H37 -> 6807.08 | D10: =H38 -> 501.56083 | E10: =H39 -> 1283.86
A11: =Supuestos!$B$6 -> 10000 | B11: =H40 -> 92.42995 | C11: =H41 -> 142.0252 | D11: =H42 -> 35.913333 | E11: =H43 -> 102.964 | F11: <- volumen base (Supuestos)
A13: Detalle por categoria
A14: Verificacion vs hoja Costos (debe ser 0): | D14: =ROUND(SUMPRODUCT(ABS(B11:E11-Costos!B36:E36)),6) -> 0
A15: Articulos/mes | B15: Modalidad | C15: Tokens | D15: Compute | E15: Almacenamiento | F15: Red | G15: Otros | H15: Total (USD/mes) | I15: USD por articulo | J15: Instancias / nodos
A16: =$A$5 -> 1000 | B16: 2.1 GCP Console | C16: =$A16*(Supuestos!$B$20*Supuestos!$B$23*1)/1000000*Supuestos!$B$32+$A16*((Supuestos!$B$21+Supuestos!$B$22*Supuestos!$B$24)*Supuestos!$B$23*1)/1000000*Supuestos!$B$33 -> 8.197875 | D16: =MAX(0,$A16*Supuestos!$B$36*1*Supuestos!$B$37+Supuestos!$B$39*Supuestos!$B$37*2592000-Supuestos!$B$43)*Supuestos!$B$40+MAX(0,$A16*Supuestos!$B$36*1*Supuestos!$B$38+Supuestos!$B$39*Supuestos!$B$38*2592000-Supuestos!$B$44)*Supuestos!$B$41+MAX(0,$A16*Supuestos!$B$9-Supuestos!$B$45)/1000000*Supuestos!$B$42 -> 0 | E16: =Supuestos!$B$54+$A16*(Supuestos!$B$8+0)*Supuestos!$B$7/1000000*Supuestos!$B$55+MAX(0,$A16*Supuestos!$B$11*1/1000000-Supuestos!$B$57)*Supuestos!$B$56 -> 10.01632 | F16: =MAX(0,$A16*Supuestos!$B$10/1000000-Supuestos!$B$61)*Supuestos!$B$60 -> 0.0048 | G16: =Supuestos!$B$58*Supuestos!$B$59 -> 0.24 | H16: =SUM(C16:G16) -> 18.458995 | I16: =IF(A16=0,0,H16/A16) -> 0.018458995 | J16: =Supuestos!$B$39 -> 0
A17: =$A$5 -> 1000 | B17: 2.2 ADK + GCP | C17: =$A17*(Supuestos!$B$20*Supuestos!$B$23*Supuestos!$B$48)/1000000*Supuestos!$B$32+$A17*((Supuestos!$B$21+Supuestos!$B$22*Supuestos!$B$24)*Supuestos!$B$23*Supuestos!$B$48)/1000000*Supuestos!$B$33 -> 13.1166 | D17: =MAX(0,$A17*Supuestos!$B$36*Supuestos!$B$49*Supuestos!$B$37+Supuestos!$B$39*Supuestos!$B$37*2592000-Supuestos!$B$43)*Supuestos!$B$40+MAX(0,$A17*Supuestos!$B$36*Supuestos!$B$49*Supuestos!$B$38+Supuestos!$B$39*Supuestos!$B$38*2592000-Supuestos!$B$44)*Supuestos!$B$41+MAX(0,$A17*Supuestos!$B$9-Supuestos!$B$45)/1000000*Supuestos!$B$42 -> 0 | E17: =Supuestos!$B$54+$A17*(Supuestos!$B$8+Supuestos!$B$50)*Supuestos!$B$7/1000000*Supuestos!$B$55+MAX(0,$A17*Supuestos!$B$11*Supuestos!$B$51/1000000-Supuestos!$B$57)*Supuestos!$B$56 -> 10.05712 | F17: =MAX(0,$A17*Supuestos!$B$10/1000000-Supuestos!$B$61)*Supuestos!$B$60 -> 0.0048 | G17: =Supuestos!$B$58*Supuestos!$B$59 -> 0.24 | H17: =SUM(C17:G17) -> 23.41852 | I17: =IF(A17=0,0,H17/A17) -> 0.02341852 | J17: =Supuestos!$B$39 -> 0
A18: =$A$5 -> 1000 | B18: 2.3-A Ollama equipo propio | C18: =0 -> 0 | D18: =MAX(1,ROUNDUP($A18*Supuestos!$B$64/3600/(Supuestos!$B$66*Supuestos!$B$65),0))*Supuestos!$B$67/Supuestos!$B$68+(($A18*Supuestos!$B$64/3600)*Supuestos!$B$69+(MAX(1,ROUNDUP($A18*Supuestos!$B$64/3600/(Supuestos!$B$66*Supuestos!$B$65),0))*Supuestos!$B$66-($A18*Supuestos!$B$64/3600))*Supuestos!$B$70)/1000*Supuestos!$B$71 -> 35.069583 | E18: =0 -> 0 | F18: =0 -> 0 | G18: =0 -> 0 | H18: =SUM(C18:G18) -> 35.069583 | I18: =IF(A18=0,0,H18/A18) -> 0.035069583 | J18: =MAX(1,ROUNDUP($A18*Supuestos!$B$64/3600/(Supuestos!$B$66*Supuestos!$B$65),0)) -> 1
A19: =$A$5 -> 1000 | B19: 2.3-B Ollama VM en nube | C19: =0 -> 0 | D19: =MAX(1,ROUNDUP($A19*Supuestos!$B$64/3600/(Supuestos!$B$66*Supuestos!$B$65),0))*Supuestos!$B$72*Supuestos!$B$66 -> 97.82 | E19: =(Supuestos!$B$73+$A19*Supuestos!$B$8*Supuestos!$B$7/1000000)*Supuestos!$B$74 -> 5.0096 | F19: =MAX(0,$A19*Supuestos!$B$10/1000000-Supuestos!$B$61)*Supuestos!$B$60 -> 0.0048 | G19: =0 -> 0 | H19: =SUM(C19:G19) -> 102.8344 | I19: =IF(A19=0,0,H19/A19) -> 0.1028344 | J19: =MAX(1,ROUNDUP($A19*Supuestos!$B$64/3600/(Supuestos!$B$66*Supuestos!$B$65),0)) -> 1
A20: =$A$6 -> 5000 | B20: 2.1 GCP Console | C20: =$A20*(Supuestos!$B$20*Supuestos!$B$23*1)/1000000*Supuestos!$B$32+$A20*((Supuestos!$B$21+Supuestos!$B$22*Supuestos!$B$24)*Supuestos!$B$23*1)/1000000*Supuestos!$B$33 -> 40.989375 | D20: =MAX(0,$A20*Supuestos!$B$36*1*Supuestos!$B$37+Supuestos!$B$39*Supuestos!$B$37*2592000-Supuestos!$B$43)*Supuestos!$B$40+MAX(0,$A20*Supuestos!$B$36*1*Supuestos!$B$38+Supuestos!$B$39*Supuestos!$B$38*2592000-Supuestos!$B$44)*Supuestos!$B$41+MAX(0,$A20*Supuestos!$B$9-Supuestos!$B$45)/1000000*Supuestos!$B$42 -> 0 | E20: =Supuestos!$B$54+$A20*(Supuestos!$B$8+0)*Supuestos!$B$7/1000000*Supuestos!$B$55+MAX(0,$A20*Supuestos!$B$11*1/1000000-Supuestos!$B$57)*Supuestos!$B$56 -> 10.0816 | F20: =MAX(0,$A20*Supuestos!$B$10/1000000-Supuestos!$B$61)*Supuestos!$B$60 -> 0.024 | G20: =Supuestos!$B$58*Supuestos!$B$59 -> 0.24 | H20: =SUM(C20:G20) -> 51.334975 | I20: =IF(A20=0,0,H20/A20) -> 0.010266995 | J20: =Supuestos!$B$39 -> 0
A21: =$A$6 -> 5000 | B21: 2.2 ADK + GCP | C21: =$A21*(Supuestos!$B$20*Supuestos!$B$23*Supuestos!$B$48)/1000000*Supuestos!$B$32+$A21*((Supuestos!$B$21+Supuestos!$B$22*Supuestos!$B$24)*Supuestos!$B$23*Supuestos!$B$48)/1000000*Supuestos!$B$33 -> 65.583 | D21: =MAX(0,$A21*Supuestos!$B$36*Supuestos!$B$49*Supuestos!$B$37+Supuestos!$B$39*Supuestos!$B$37*2592000-Supuestos!$B$43)*Supuestos!$B$40+MAX(0,$A21*Supuestos!$B$36*Supuestos!$B$49*Supuestos!$B$38+Supuestos!$B$39*Supuestos!$B$38*2592000-Supuestos!$B$44)*Supuestos!$B$41+MAX(0,$A21*Supuestos!$B$9-Supuestos!$B$45)/1000000*Supuestos!$B$42 -> 0 | E21: =Supuestos!$B$54+$A21*(Supuestos!$B$8+Supuestos!$B$50)*Supuestos!$B$7/1000000*Supuestos!$B$55+MAX(0,$A21*Supuestos!$B$11*Supuestos!$B$51/1000000-Supuestos!$B$57)*Supuestos!$B$56 -> 10.2856 | F21: =MAX(0,$A21*Supuestos!$B$10/1000000-Supuestos!$B$61)*Supuestos!$B$60 -> 0.024 | G21: =Supuestos!$B$58*Supuestos!$B$59 -> 0.24 | H21: =SUM(C21:G21) -> 76.1326 | I21: =IF(A21=0,0,H21/A21) -> 0.01522652 | J21: =Supuestos!$B$39 -> 0
A22: =$A$6 -> 5000 | B22: 2.3-A Ollama equipo propio | C22: =0 -> 0 | D22: =MAX(1,ROUNDUP($A22*Supuestos!$B$64/3600/(Supuestos!$B$66*Supuestos!$B$65),0))*Supuestos!$B$67/Supuestos!$B$68+(($A22*Supuestos!$B$64/3600)*Supuestos!$B$69+(MAX(1,ROUNDUP($A22*Supuestos!$B$64/3600/(Supuestos!$B$66*Supuestos!$B$65),0))*Supuestos!$B$66-($A22*Supuestos!$B$64/3600))*Supuestos!$B$70)/1000*Supuestos!$B$71 -> 35.444583 | E22: =0 -> 0 | F22: =0 -> 0 | G22: =0 -> 0 | H22: =SUM(C22:G22) -> 35.444583 | I22: =IF(A22=0,0,H22/A22) -> 0.0070889167 | J22: =MAX(1,ROUNDUP($A22*Supuestos!$B$64/3600/(Supuestos!$B$66*Supuestos!$B$65),0)) -> 1
A23: =$A$6 -> 5000 | B23: 2.3-B Ollama VM en nube | C23: =0 -> 0 | D23: =MAX(1,ROUNDUP($A23*Supuestos!$B$64/3600/(Supuestos!$B$66*Supuestos!$B$65),0))*Supuestos!$B$72*Supuestos!$B$66 -> 97.82 | E23: =(Supuestos!$B$73+$A23*Supuestos!$B$8*Supuestos!$B$7/1000000)*Supuestos!$B$74 -> 5.048 | F23: =MAX(0,$A23*Supuestos!$B$10/1000000-Supuestos!$B$61)*Supuestos!$B$60 -> 0.024 | G23: =0 -> 0 | H23: =SUM(C23:G23) -> 102.892 | I23: =IF(A23=0,0,H23/A23) -> 0.0205784 | J23: =MAX(1,ROUNDUP($A23*Supuestos!$B$64/3600/(Supuestos!$B$66*Supuestos!$B$65),0)) -> 1
A24: =$A$7 -> 10000 | B24: 2.1 GCP Console | C24: =$A24*(Supuestos!$B$20*Supuestos!$B$23*1)/1000000*Supuestos!$B$32+$A24*((Supuestos!$B$21+Supuestos!$B$22*Supuestos!$B$24)*Supuestos!$B$23*1)/1000000*Supuestos!$B$33 -> 81.97875 | D24: =MAX(0,$A24*Supuestos!$B$36*1*Supuestos!$B$37+Supuestos!$B$39*Supuestos!$B$37*2592000-Supuestos!$B$43)*Supuestos!$B$40+MAX(0,$A24*Supuestos!$B$36*1*Supuestos!$B$38+Supuestos!$B$39*Supuestos!$B$38*2592000-Supuestos!$B$44)*Supuestos!$B$41+MAX(0,$A24*Supuestos!$B$9-Supuestos!$B$45)/1000000*Supuestos!$B$42 -> 0 | E24: =Supuestos!$B$54+$A24*(Supuestos!$B$8+0)*Supuestos!$B$7/1000000*Supuestos!$B$55+MAX(0,$A24*Supuestos!$B$11*1/1000000-Supuestos!$B$57)*Supuestos!$B$56 -> 10.1632 | F24: =MAX(0,$A24*Supuestos!$B$10/1000000-Supuestos!$B$61)*Supuestos!$B$60 -> 0.048 | G24: =Supuestos!$B$58*Supuestos!$B$59 -> 0.24 | H24: =SUM(C24:G24) -> 92.42995 | I24: =IF(A24=0,0,H24/A24) -> 0.009242995 | J24: =Supuestos!$B$39 -> 0
A25: =$A$7 -> 10000 | B25: 2.2 ADK + GCP | C25: =$A25*(Supuestos!$B$20*Supuestos!$B$23*Supuestos!$B$48)/1000000*Supuestos!$B$32+$A25*((Supuestos!$B$21+Supuestos!$B$22*Supuestos!$B$24)*Supuestos!$B$23*Supuestos!$B$48)/1000000*Supuestos!$B$33 -> 131.166 | D25: =MAX(0,$A25*Supuestos!$B$36*Supuestos!$B$49*Supuestos!$B$37+Supuestos!$B$39*Supuestos!$B$37*2592000-Supuestos!$B$43)*Supuestos!$B$40+MAX(0,$A25*Supuestos!$B$36*Supuestos!$B$49*Supuestos!$B$38+Supuestos!$B$39*Supuestos!$B$38*2592000-Supuestos!$B$44)*Supuestos!$B$41+MAX(0,$A25*Supuestos!$B$9-Supuestos!$B$45)/1000000*Supuestos!$B$42 -> 0 | E25: =Supuestos!$B$54+$A25*(Supuestos!$B$8+Supuestos!$B$50)*Supuestos!$B$7/1000000*Supuestos!$B$55+MAX(0,$A25*Supuestos!$B$11*Supuestos!$B$51/1000000-Supuestos!$B$57)*Supuestos!$B$56 -> 10.5712 | F25: =MAX(0,$A25*Supuestos!$B$10/1000000-Supuestos!$B$61)*Supuestos!$B$60 -> 0.048 | G25: =Supuestos!$B$58*Supuestos!$B$59 -> 0.24 | H25: =SUM(C25:G25) -> 142.0252 | I25: =IF(A25=0,0,H25/A25) -> 0.01420252 | J25: =Supuestos!$B$39 -> 0
A26: =$A$7 -> 10000 | B26: 2.3-A Ollama equipo propio | C26: =0 -> 0 | D26: =MAX(1,ROUNDUP($A26*Supuestos!$B$64/3600/(Supuestos!$B$66*Supuestos!$B$65),0))*Supuestos!$B$67/Supuestos!$B$68+(($A26*Supuestos!$B$64/3600)*Supuestos!$B$69+(MAX(1,ROUNDUP($A26*Supuestos!$B$64/3600/(Supuestos!$B$66*Supuestos!$B$65),0))*Supuestos!$B$66-($A26*Supuestos!$B$64/3600))*Supuestos!$B$70)/1000*Supuestos!$B$71 -> 35.913333 | E26: =0 -> 0 | F26: =0 -> 0 | G26: =0 -> 0 | H26: =SUM(C26:G26) -> 35.913333 | I26: =IF(A26=0,0,H26/A26) -> 0.0035913333 | J26: =MAX(1,ROUNDUP($A26*Supuestos!$B$64/3600/(Supuestos!$B$66*Supuestos!$B$65),0)) -> 1
A27: =$A$7 -> 10000 | B27: 2.3-B Ollama VM en nube | C27: =0 -> 0 | D27: =MAX(1,ROUNDUP($A27*Supuestos!$B$64/3600/(Supuestos!$B$66*Supuestos!$B$65),0))*Supuestos!$B$72*Supuestos!$B$66 -> 97.82 | E27: =(Supuestos!$B$73+$A27*Supuestos!$B$8*Supuestos!$B$7/1000000)*Supuestos!$B$74 -> 5.096 | F27: =MAX(0,$A27*Supuestos!$B$10/1000000-Supuestos!$B$61)*Supuestos!$B$60 -> 0.048 | G27: =0 -> 0 | H27: =SUM(C27:G27) -> 102.964 | I27: =IF(A27=0,0,H27/A27) -> 0.0102964 | J27: =MAX(1,ROUNDUP($A27*Supuestos!$B$64/3600/(Supuestos!$B$66*Supuestos!$B$65),0)) -> 1
A28: =$A$8 -> 50000 | B28: 2.1 GCP Console | C28: =$A28*(Supuestos!$B$20*Supuestos!$B$23*1)/1000000*Supuestos!$B$32+$A28*((Supuestos!$B$21+Supuestos!$B$22*Supuestos!$B$24)*Supuestos!$B$23*1)/1000000*Supuestos!$B$33 -> 409.89375 | D28: =MAX(0,$A28*Supuestos!$B$36*1*Supuestos!$B$37+Supuestos!$B$39*Supuestos!$B$37*2592000-Supuestos!$B$43)*Supuestos!$B$40+MAX(0,$A28*Supuestos!$B$36*1*Supuestos!$B$38+Supuestos!$B$39*Supuestos!$B$38*2592000-Supuestos!$B$44)*Supuestos!$B$41+MAX(0,$A28*Supuestos!$B$9-Supuestos!$B$45)/1000000*Supuestos!$B$42 -> 8.03 | E28: =Supuestos!$B$54+$A28*(Supuestos!$B$8+0)*Supuestos!$B$7/1000000*Supuestos!$B$55+MAX(0,$A28*Supuestos!$B$11*1/1000000-Supuestos!$B$57)*Supuestos!$B$56 -> 10.816 | F28: =MAX(0,$A28*Supuestos!$B$10/1000000-Supuestos!$B$61)*Supuestos!$B$60 -> 0.24 | G28: =Supuestos!$B$58*Supuestos!$B$59 -> 0.24 | H28: =SUM(C28:G28) -> 429.21975 | I28: =IF(A28=0,0,H28/A28) -> 0.008584395 | J28: =Supuestos!$B$39 -> 0
A29: =$A$8 -> 50000 | B29: 2.2 ADK + GCP | C29: =$A29*(Supuestos!$B$20*Supuestos!$B$23*Supuestos!$B$48)/1000000*Supuestos!$B$32+$A29*((Supuestos!$B$21+Supuestos!$B$22*Supuestos!$B$24)*Supuestos!$B$23*Supuestos!$B$48)/1000000*Supuestos!$B$33 -> 655.83 | D29: =MAX(0,$A29*Supuestos!$B$36*Supuestos!$B$49*Supuestos!$B$37+Supuestos!$B$39*Supuestos!$B$37*2592000-Supuestos!$B$43)*Supuestos!$B$40+MAX(0,$A29*Supuestos!$B$36*Supuestos!$B$49*Supuestos!$B$38+Supuestos!$B$39*Supuestos!$B$38*2592000-Supuestos!$B$44)*Supuestos!$B$41+MAX(0,$A29*Supuestos!$B$9-Supuestos!$B$45)/1000000*Supuestos!$B$42 -> 15.98 | E29: =Supuestos!$B$54+$A29*(Supuestos!$B$8+Supuestos!$B$50)*Supuestos!$B$7/1000000*Supuestos!$B$55+MAX(0,$A29*Supuestos!$B$11*Supuestos!$B$51/1000000-Supuestos!$B$57)*Supuestos!$B$56 -> 12.856 | F29: =MAX(0,$A29*Supuestos!$B$10/1000000-Supuestos!$B$61)*Supuestos!$B$60 -> 0.24 | G29: =Supuestos!$B$58*Supuestos!$B$59 -> 0.24 | H29: =SUM(C29:G29) -> 685.146 | I29: =IF(A29=0,0,H29/A29) -> 0.01370292 | J29: =Supuestos!$B$39 -> 0
A30: =$A$8 -> 50000 | B30: 2.3-A Ollama equipo propio | C30: =0 -> 0 | D30: =MAX(1,ROUNDUP($A30*Supuestos!$B$64/3600/(Supuestos!$B$66*Supuestos!$B$65),0))*Supuestos!$B$67/Supuestos!$B$68+(($A30*Supuestos!$B$64/3600)*Supuestos!$B$69+(MAX(1,ROUNDUP($A30*Supuestos!$B$64/3600/(Supuestos!$B$66*Supuestos!$B$65),0))*Supuestos!$B$66-($A30*Supuestos!$B$64/3600))*Supuestos!$B$70)/1000*Supuestos!$B$71 -> 74.639167 | E30: =0 -> 0 | F30: =0 -> 0 | G30: =0 -> 0 | H30: =SUM(C30:G30) -> 74.639167 | I30: =IF(A30=0,0,H30/A30) -> 0.0014927833 | J30: =MAX(1,ROUNDUP($A30*Supuestos!$B$64/3600/(Supuestos!$B$66*Supuestos!$B$65),0)) -> 2
A31: =$A$8 -> 50000 | B31: 2.3-B Ollama VM en nube | C31: =0 -> 0 | D31: =MAX(1,ROUNDUP($A31*Supuestos!$B$64/3600/(Supuestos!$B$66*Supuestos!$B$65),0))*Supuestos!$B$72*Supuestos!$B$66 -> 195.64 | E31: =(Supuestos!$B$73+$A31*Supuestos!$B$8*Supuestos!$B$7/1000000)*Supuestos!$B$74 -> 5.48 | F31: =MAX(0,$A31*Supuestos!$B$10/1000000-Supuestos!$B$61)*Supuestos!$B$60 -> 0.24 | G31: =0 -> 0 | H31: =SUM(C31:G31) -> 201.36 | I31: =IF(A31=0,0,H31/A31) -> 0.0040272 | J31: =MAX(1,ROUNDUP($A31*Supuestos!$B$64/3600/(Supuestos!$B$66*Supuestos!$B$65),0)) -> 2
A32: =$A$9 -> 100000 | B32: 2.1 GCP Console | C32: =$A32*(Supuestos!$B$20*Supuestos!$B$23*1)/1000000*Supuestos!$B$32+$A32*((Supuestos!$B$21+Supuestos!$B$22*Supuestos!$B$24)*Supuestos!$B$23*1)/1000000*Supuestos!$B$33 -> 819.7875 | D32: =MAX(0,$A32*Supuestos!$B$36*1*Supuestos!$B$37+Supuestos!$B$39*Supuestos!$B$37*2592000-Supuestos!$B$43)*Supuestos!$B$40+MAX(0,$A32*Supuestos!$B$36*1*Supuestos!$B$38+Supuestos!$B$39*Supuestos!$B$38*2592000-Supuestos!$B$44)*Supuestos!$B$41+MAX(0,$A32*Supuestos!$B$9-Supuestos!$B$45)/1000000*Supuestos!$B$42 -> 21.28 | E32: =Supuestos!$B$54+$A32*(Supuestos!$B$8+0)*Supuestos!$B$7/1000000*Supuestos!$B$55+MAX(0,$A32*Supuestos!$B$11*1/1000000-Supuestos!$B$57)*Supuestos!$B$56 -> 11.632 | F32: =MAX(0,$A32*Supuestos!$B$10/1000000-Supuestos!$B$61)*Supuestos!$B$60 -> 0.48 | G32: =Supuestos!$B$58*Supuestos!$B$59 -> 0.24 | H32: =SUM(C32:G32) -> 853.4195 | I32: =IF(A32=0,0,H32/A32) -> 0.008534195 | J32: =Supuestos!$B$39 -> 0
A33: =$A$9 -> 100000 | B33: 2.2 ADK + GCP | C33: =$A33*(Supuestos!$B$20*Supuestos!$B$23*Supuestos!$B$48)/1000000*Supuestos!$B$32+$A33*((Supuestos!$B$21+Supuestos!$B$22*Supuestos!$B$24)*Supuestos!$B$23*Supuestos!$B$48)/1000000*Supuestos!$B$33 -> 1311.66 | D33: =MAX(0,$A33*Supuestos!$B$36*Supuestos!$B$49*Supuestos!$B$37+Supuestos!$B$39*Supuestos!$B$37*2592000-Supuestos!$B$43)*Supuestos!$B$40+MAX(0,$A33*Supuestos!$B$36*Supuestos!$B$49*Supuestos!$B$38+Supuestos!$B$39*Supuestos!$B$38*2592000-Supuestos!$B$44)*Supuestos!$B$41+MAX(0,$A33*Supuestos!$B$9-Supuestos!$B$45)/1000000*Supuestos!$B$42 -> 37.18 | E33: =Supuestos!$B$54+$A33*(Supuestos!$B$8+Supuestos!$B$50)*Supuestos!$B$7/1000000*Supuestos!$B$55+MAX(0,$A33*Supuestos!$B$11*Supuestos!$B$51/1000000-Supuestos!$B$57)*Supuestos!$B$56 -> 15.712 | F33: =MAX(0,$A33*Supuestos!$B$10/1000000-Supuestos!$B$61)*Supuestos!$B$60 -> 0.48 | G33: =Supuestos!$B$58*Supuestos!$B$59 -> 0.24 | H33: =SUM(C33:G33) -> 1365.272 | I33: =IF(A33=0,0,H33/A33) -> 0.01365272 | J33: =Supuestos!$B$39 -> 0
A34: =$A$9 -> 100000 | B34: 2.3-A Ollama equipo propio | C34: =0 -> 0 | D34: =MAX(1,ROUNDUP($A34*Supuestos!$B$64/3600/(Supuestos!$B$66*Supuestos!$B$65),0))*Supuestos!$B$67/Supuestos!$B$68+(($A34*Supuestos!$B$64/3600)*Supuestos!$B$69+(MAX(1,ROUNDUP($A34*Supuestos!$B$64/3600/(Supuestos!$B$66*Supuestos!$B$65),0))*Supuestos!$B$66-($A34*Supuestos!$B$64/3600))*Supuestos!$B$70)/1000*Supuestos!$B$71 -> 114.3025 | E34: =0 -> 0 | F34: =0 -> 0 | G34: =0 -> 0 | H34: =SUM(C34:G34) -> 114.3025 | I34: =IF(A34=0,0,H34/A34) -> 0.001143025 | J34: =MAX(1,ROUNDUP($A34*Supuestos!$B$64/3600/(Supuestos!$B$66*Supuestos!$B$65),0)) -> 3
A35: =$A$9 -> 100000 | B35: 2.3-B Ollama VM en nube | C35: =0 -> 0 | D35: =MAX(1,ROUNDUP($A35*Supuestos!$B$64/3600/(Supuestos!$B$66*Supuestos!$B$65),0))*Supuestos!$B$72*Supuestos!$B$66 -> 293.46 | E35: =(Supuestos!$B$73+$A35*Supuestos!$B$8*Supuestos!$B$7/1000000)*Supuestos!$B$74 -> 5.96 | F35: =MAX(0,$A35*Supuestos!$B$10/1000000-Supuestos!$B$61)*Supuestos!$B$60 -> 0.48 | G35: =0 -> 0 | H35: =SUM(C35:G35) -> 299.9 | I35: =IF(A35=0,0,H35/A35) -> 0.002999 | J35: =MAX(1,ROUNDUP($A35*Supuestos!$B$64/3600/(Supuestos!$B$66*Supuestos!$B$65),0)) -> 3
A36: =$A$10 -> 500000 | B36: 2.1 GCP Console | C36: =$A36*(Supuestos!$B$20*Supuestos!$B$23*1)/1000000*Supuestos!$B$32+$A36*((Supuestos!$B$21+Supuestos!$B$22*Supuestos!$B$24)*Supuestos!$B$23*1)/1000000*Supuestos!$B$33 -> 4098.9375 | D36: =MAX(0,$A36*Supuestos!$B$36*1*Supuestos!$B$37+Supuestos!$B$39*Supuestos!$B$37*2592000-Supuestos!$B$43)*Supuestos!$B$40+MAX(0,$A36*Supuestos!$B$36*1*Supuestos!$B$38+Supuestos!$B$39*Supuestos!$B$38*2592000-Supuestos!$B$44)*Supuestos!$B$41+MAX(0,$A36*Supuestos!$B$9-Supuestos!$B$45)/1000000*Supuestos!$B$42 -> 128.08 | E36: =Supuestos!$B$54+$A36*(Supuestos!$B$8+0)*Supuestos!$B$7/1000000*Supuestos!$B$55+MAX(0,$A36*Supuestos!$B$11*1/1000000-Supuestos!$B$57)*Supuestos!$B$56 -> 18.16 | F36: =MAX(0,$A36*Supuestos!$B$10/1000000-Supuestos!$B$61)*Supuestos!$B$60 -> 2.4 | G36: =Supuestos!$B$58*Supuestos!$B$59 -> 0.24 | H36: =SUM(C36:G36) -> 4247.8175 | I36: =IF(A36=0,0,H36/A36) -> 0.008495635 | J36: =Supuestos!$B$39 -> 0
A37: =$A$10 -> 500000 | B37: 2.2 ADK + GCP | C37: =$A37*(Supuestos!$B$20*Supuestos!$B$23*Supuestos!$B$48)/1000000*Supuestos!$B$32+$A37*((Supuestos!$B$21+Supuestos!$B$22*Supuestos!$B$24)*Supuestos!$B$23*Supuestos!$B$48)/1000000*Supuestos!$B$33 -> 6558.3 | D37: =MAX(0,$A37*Supuestos!$B$36*Supuestos!$B$49*Supuestos!$B$37+Supuestos!$B$39*Supuestos!$B$37*2592000-Supuestos!$B$43)*Supuestos!$B$40+MAX(0,$A37*Supuestos!$B$36*Supuestos!$B$49*Supuestos!$B$38+Supuestos!$B$39*Supuestos!$B$38*2592000-Supuestos!$B$44)*Supuestos!$B$41+MAX(0,$A37*Supuestos!$B$9-Supuestos!$B$45)/1000000*Supuestos!$B$42 -> 207.58 | E37: =Supuestos!$B$54+$A37*(Supuestos!$B$8+Supuestos!$B$50)*Supuestos!$B$7/1000000*Supuestos!$B$55+MAX(0,$A37*Supuestos!$B$11*Supuestos!$B$51/1000000-Supuestos!$B$57)*Supuestos!$B$56 -> 38.56 | F37: =MAX(0,$A37*Supuestos!$B$10/1000000-Supuestos!$B$61)*Supuestos!$B$60 -> 2.4 | G37: =Supuestos!$B$58*Supuestos!$B$59 -> 0.24 | H37: =SUM(C37:G37) -> 6807.08 | I37: =IF(A37=0,0,H37/A37) -> 0.01361416 | J37: =Supuestos!$B$39 -> 0
A38: =$A$10 -> 500000 | B38: 2.3-A Ollama equipo propio | C38: =0 -> 0 | D38: =MAX(1,ROUNDUP($A38*Supuestos!$B$64/3600/(Supuestos!$B$66*Supuestos!$B$65),0))*Supuestos!$B$67/Supuestos!$B$68+(($A38*Supuestos!$B$64/3600)*Supuestos!$B$69+(MAX(1,ROUNDUP($A38*Supuestos!$B$64/3600/(Supuestos!$B$66*Supuestos!$B$65),0))*Supuestos!$B$66-($A38*Supuestos!$B$64/3600))*Supuestos!$B$70)/1000*Supuestos!$B$71 -> 501.56083 | E38: =0 -> 0 | F38: =0 -> 0 | G38: =0 -> 0 | H38: =SUM(C38:G38) -> 501.56083 | I38: =IF(A38=0,0,H38/A38) -> 0.0010031217 | J38: =MAX(1,ROUNDUP($A38*Supuestos!$B$64/3600/(Supuestos!$B$66*Supuestos!$B$65),0)) -> 13
A39: =$A$10 -> 500000 | B39: 2.3-B Ollama VM en nube | C39: =0 -> 0 | D39: =MAX(1,ROUNDUP($A39*Supuestos!$B$64/3600/(Supuestos!$B$66*Supuestos!$B$65),0))*Supuestos!$B$72*Supuestos!$B$66 -> 1271.66 | E39: =(Supuestos!$B$73+$A39*Supuestos!$B$8*Supuestos!$B$7/1000000)*Supuestos!$B$74 -> 9.8 | F39: =MAX(0,$A39*Supuestos!$B$10/1000000-Supuestos!$B$61)*Supuestos!$B$60 -> 2.4 | G39: =0 -> 0 | H39: =SUM(C39:G39) -> 1283.86 | I39: =IF(A39=0,0,H39/A39) -> 0.00256772 | J39: =MAX(1,ROUNDUP($A39*Supuestos!$B$64/3600/(Supuestos!$B$66*Supuestos!$B$65),0)) -> 13
A40: =$A$11 -> 10000 | B40: 2.1 GCP Console | C40: =$A40*(Supuestos!$B$20*Supuestos!$B$23*1)/1000000*Supuestos!$B$32+$A40*((Supuestos!$B$21+Supuestos!$B$22*Supuestos!$B$24)*Supuestos!$B$23*1)/1000000*Supuestos!$B$33 -> 81.97875 | D40: =MAX(0,$A40*Supuestos!$B$36*1*Supuestos!$B$37+Supuestos!$B$39*Supuestos!$B$37*2592000-Supuestos!$B$43)*Supuestos!$B$40+MAX(0,$A40*Supuestos!$B$36*1*Supuestos!$B$38+Supuestos!$B$39*Supuestos!$B$38*2592000-Supuestos!$B$44)*Supuestos!$B$41+MAX(0,$A40*Supuestos!$B$9-Supuestos!$B$45)/1000000*Supuestos!$B$42 -> 0 | E40: =Supuestos!$B$54+$A40*(Supuestos!$B$8+0)*Supuestos!$B$7/1000000*Supuestos!$B$55+MAX(0,$A40*Supuestos!$B$11*1/1000000-Supuestos!$B$57)*Supuestos!$B$56 -> 10.1632 | F40: =MAX(0,$A40*Supuestos!$B$10/1000000-Supuestos!$B$61)*Supuestos!$B$60 -> 0.048 | G40: =Supuestos!$B$58*Supuestos!$B$59 -> 0.24 | H40: =SUM(C40:G40) -> 92.42995 | I40: =IF(A40=0,0,H40/A40) -> 0.009242995 | J40: =Supuestos!$B$39 -> 0
A41: =$A$11 -> 10000 | B41: 2.2 ADK + GCP | C41: =$A41*(Supuestos!$B$20*Supuestos!$B$23*Supuestos!$B$48)/1000000*Supuestos!$B$32+$A41*((Supuestos!$B$21+Supuestos!$B$22*Supuestos!$B$24)*Supuestos!$B$23*Supuestos!$B$48)/1000000*Supuestos!$B$33 -> 131.166 | D41: =MAX(0,$A41*Supuestos!$B$36*Supuestos!$B$49*Supuestos!$B$37+Supuestos!$B$39*Supuestos!$B$37*2592000-Supuestos!$B$43)*Supuestos!$B$40+MAX(0,$A41*Supuestos!$B$36*Supuestos!$B$49*Supuestos!$B$38+Supuestos!$B$39*Supuestos!$B$38*2592000-Supuestos!$B$44)*Supuestos!$B$41+MAX(0,$A41*Supuestos!$B$9-Supuestos!$B$45)/1000000*Supuestos!$B$42 -> 0 | E41: =Supuestos!$B$54+$A41*(Supuestos!$B$8+Supuestos!$B$50)*Supuestos!$B$7/1000000*Supuestos!$B$55+MAX(0,$A41*Supuestos!$B$11*Supuestos!$B$51/1000000-Supuestos!$B$57)*Supuestos!$B$56 -> 10.5712 | F41: =MAX(0,$A41*Supuestos!$B$10/1000000-Supuestos!$B$61)*Supuestos!$B$60 -> 0.048 | G41: =Supuestos!$B$58*Supuestos!$B$59 -> 0.24 | H41: =SUM(C41:G41) -> 142.0252 | I41: =IF(A41=0,0,H41/A41) -> 0.01420252 | J41: =Supuestos!$B$39 -> 0
A42: =$A$11 -> 10000 | B42: 2.3-A Ollama equipo propio | C42: =0 -> 0 | D42: =MAX(1,ROUNDUP($A42*Supuestos!$B$64/3600/(Supuestos!$B$66*Supuestos!$B$65),0))*Supuestos!$B$67/Supuestos!$B$68+(($A42*Supuestos!$B$64/3600)*Supuestos!$B$69+(MAX(1,ROUNDUP($A42*Supuestos!$B$64/3600/(Supuestos!$B$66*Supuestos!$B$65),0))*Supuestos!$B$66-($A42*Supuestos!$B$64/3600))*Supuestos!$B$70)/1000*Supuestos!$B$71 -> 35.913333 | E42: =0 -> 0 | F42: =0 -> 0 | G42: =0 -> 0 | H42: =SUM(C42:G42) -> 35.913333 | I42: =IF(A42=0,0,H42/A42) -> 0.0035913333 | J42: =MAX(1,ROUNDUP($A42*Supuestos!$B$64/3600/(Supuestos!$B$66*Supuestos!$B$65),0)) -> 1
...

Sheet Notas y fuentes
A1: Notas, fuentes y limitaciones
A3: FUENTES (consultadas el 21-oct-2026)
A4: Vertex AI - precios de Gemini | B4: https://cloud.google.com/vertex-ai/generative-ai/pricing. Gemini 3.6/3.7/3.8 Flash: USD 0.75 / 3.75 por 1M tokens (entrada/salida) hasta el 31-dic-2026; desde el 1-ene-2027, USD 1.5 / 7.5. Debe coincidir con el modelo que realmente uses.
A5: Cloud Run - precios | B5: Pagina oficial: https://cloud.google.com/run/pricing (el extracto consultado no mostraba las cifras). Valores tomados de resumenes de terceros: https://tech-insider.org/how-to-set-up-google-cloud-run-2026/ y https://cubeapm.com/ (egreso USD 0.12/GiB). Hay una fuente que indica una rebaja a USD 0.000018/vCPU-s y 0.000002/GiB-s: se uso la tarifa mayor por prudencia.
A6: Datos NO verificados en esta sesion | B6: Cloud Logging, Secret Manager, base de datos gestionada, VM e2-standard-4 y disco persistente: valores de referencia de memoria. Confirmar en https://cloud.google.com/products/calculator.
A7: Supuestos del equipo | B7: Volumen, tamanos de datos, solicitudes por articulo, segundos por articulo, costo de equipo, consumo electrico y tarifa de electricidad son estimaciones. Reemplazarlas por mediciones.
A8: LIMITACIONES DEL MODELO
A9: Cloud Run y BackgroundTasks | B9: Con facturacion por solicitud, la CPU se limita cuando la respuesta ya fue enviada; el pipeline asincrono necesita CPU siempre asignada, procesar dentro de la solicitud o una cola (Cloud Tasks). Esto puede subir el costo de compute respecto de la hoja.
A10: Costos no incluidos | B10: Mano de obra, mantenimiento, monitoreo, impuestos, creditos o descuentos de GCP, respaldo, alta disponibilidad, costo de revision manual por errores del modelo.
A11: Escalado local | B11: Un nodo se dimensiona con la latencia hipotetica por articulo. Con GPU el calculo cambia (mas caro por nodo, mucho mas rapido). Medir con backend/scripts/benchmark_ollama.py.
A12: Datos gratuitos | B12: Las capas gratuitas de Cloud Run se aplican por cuenta de facturacion; pueden estar consumidas por otros servicios.
